2024-10-20 14:35:58,977 [ ERROR  ] (dispatcher.py:_process_update:315): Cause exception while process update id=758780715 by bot id=8144851601
ProgrammingError: (sqlalchemy.dialects.postgresql.asyncpg.ProgrammingError) <class 'asyncpg.exceptions.UndefinedColumnError'>: column sub_category.departments does not exist
[SQL: SELECT sub_category.id, sub_category.name, sub_category.article, sub_category.departments 
FROM sub_category 
WHERE sub_category.article = $1::VARCHAR]
[parameters: ('M',)]
(Background on this error at: https://sqlalche.me/e/20/f405)
Traceback (most recent call last):
  File "C:\Users\NONE\Desktop\pythoN\jopa\.venv\Lib\site-packages\sqlalchemy\dialects\postgresql\asyncpg.py", line 510, in _prepare_and_execute
    prepared_stmt, attributes = await adapt_connection._prepare(
                                ^^^^^^^^^^^^^^^^^^^^^^^^^^^^^^^^
  File "C:\Users\NONE\Desktop\pythoN\jopa\.venv\Lib\site-packages\sqlalchemy\dialects\postgresql\asyncpg.py", line 756, in _prepare
    prepared_stmt = await self._connection.prepare(
                    ^^^^^^^^^^^^^^^^^^^^^^^^^^^^^^^
  File "C:\Users\NONE\Desktop\pythoN\jopa\.venv\Lib\site-packages\asyncpg\connection.py", line 636, in prepare
    return await self._prepare(
           ^^^^^^^^^^^^^^^^^^^^
  File "C:\Users\NONE\Desktop\pythoN\jopa\.venv\Lib\site-packages\asyncpg\connection.py", line 654, in _prepare
    stmt = await self._get_statement(
           ^^^^^^^^^^^^^^^^^^^^^^^^^^
  File "C:\Users\NONE\Desktop\pythoN\jopa\.venv\Lib\site-packages\asyncpg\connection.py", line 433, in _get_statement
    statement = await self._protocol.prepare(
                ^^^^^^^^^^^^^^^^^^^^^^^^^^^^^
  File "asyncpg\protocol\protocol.pyx", line 166, in prepare
asyncpg.exceptions.UndefinedColumnError: column sub_category.departments does not exist

The above exception was the direct cause of the following exception:

Traceback (most recent call last):
  File "C:\Users\NONE\Desktop\pythoN\jopa\.venv\Lib\site-packages\sqlalchemy\engine\base.py", line 1967, in _exec_single_context
    self.dialect.do_execute(
  File "C:\Users\NONE\Desktop\pythoN\jopa\.venv\Lib\site-packages\sqlalchemy\engine\default.py", line 941, in do_execute
    cursor.execute(statement, parameters)
  File "C:\Users\NONE\Desktop\pythoN\jopa\.venv\Lib\site-packages\sqlalchemy\dialects\postgresql\asyncpg.py", line 568, in execute
    self._adapt_connection.await_(
  File "C:\Users\NONE\Desktop\pythoN\jopa\.venv\Lib\site-packages\sqlalchemy\util\_concurrency_py3k.py", line 132, in await_only
    return current.parent.switch(awaitable)  # type: ignore[no-any-return,attr-defined] # noqa: E501
           ^^^^^^^^^^^^^^^^^^^^^^^^^^^^^^^^
  File "C:\Users\NONE\Desktop\pythoN\jopa\.venv\Lib\site-packages\sqlalchemy\util\_concurrency_py3k.py", line 196, in greenlet_spawn
    value = await result
            ^^^^^^^^^^^^
  File "C:\Users\NONE\Desktop\pythoN\jopa\.venv\Lib\site-packages\sqlalchemy\dialects\postgresql\asyncpg.py", line 546, in _prepare_and_execute
    self._handle_exception(error)
  File "C:\Users\NONE\Desktop\pythoN\jopa\.venv\Lib\site-packages\sqlalchemy\dialects\postgresql\asyncpg.py", line 497, in _handle_exception
    self._adapt_connection._handle_exception(error)
  File "C:\Users\NONE\Desktop\pythoN\jopa\.venv\Lib\site-packages\sqlalchemy\dialects\postgresql\asyncpg.py", line 780, in _handle_exception
    raise translated_error from error
sqlalchemy.dialects.postgresql.asyncpg.AsyncAdapt_asyncpg_dbapi.ProgrammingError: <class 'asyncpg.exceptions.UndefinedColumnError'>: column sub_category.departments does not exist

The above exception was the direct cause of the following exception:

Traceback (most recent call last):
  File "C:\Users\NONE\Desktop\pythoN\jopa\.venv\Lib\site-packages\aiogram\dispatcher\dispatcher.py", line 309, in _process_update
    response = await self.feed_update(bot, update, **kwargs)
               ^^^^^^^^^^^^^^^^^^^^^^^^^^^^^^^^^^^^^^^^^^^^^
  File "C:\Users\NONE\Desktop\pythoN\jopa\.venv\Lib\site-packages\aiogram\dispatcher\dispatcher.py", line 158, in feed_update
    response = await self.update.wrap_outer_middleware(
               ^^^^^^^^^^^^^^^^^^^^^^^^^^^^^^^^^^^^^^^^
  File "C:\Users\NONE\Desktop\pythoN\jopa\.venv\Lib\site-packages\aiogram\dispatcher\middlewares\error.py", line 25, in __call__
    return await handler(event, data)
           ^^^^^^^^^^^^^^^^^^^^^^^^^^
  File "C:\Users\NONE\Desktop\pythoN\jopa\.venv\Lib\site-packages\aiogram\dispatcher\middlewares\user_context.py", line 56, in __call__
    return await handler(event, data)
           ^^^^^^^^^^^^^^^^^^^^^^^^^^
  File "C:\Users\NONE\AppData\Local\Programs\Python\Python311\Lib\contextlib.py", line 222, in __aexit__
    await self.gen.athrow(typ, value, traceback)
  File "C:\Users\NONE\Desktop\pythoN\jopa\.venv\Lib\site-packages\aiogram\fsm\storage\memory.py", line 56, in lock
    yield
  File "C:\Users\NONE\Desktop\pythoN\jopa\.venv\Lib\site-packages\aiogram\fsm\middleware.py", line 42, in __call__
    return await handler(event, data)
           ^^^^^^^^^^^^^^^^^^^^^^^^^^
  File "C:\Users\NONE\Desktop\pythoN\jopa\.venv\Lib\site-packages\aiogram\dispatcher\event\telegram.py", line 121, in trigger
    return await wrapped_inner(event, kwargs)
           ^^^^^^^^^^^^^^^^^^^^^^^^^^^^^^^^^^
  File "C:\Users\NONE\Desktop\pythoN\jopa\.venv\Lib\site-packages\aiogram\dispatcher\event\handler.py", line 43, in call
    return await wrapped()
           ^^^^^^^^^^^^^^^
  File "C:\Users\NONE\Desktop\pythoN\jopa\.venv\Lib\site-packages\aiogram\dispatcher\dispatcher.py", line 276, in _listen_update
    return await self.propagate_event(update_type=update_type, event=event, **kwargs)
           ^^^^^^^^^^^^^^^^^^^^^^^^^^^^^^^^^^^^^^^^^^^^^^^^^^^^^^^^^^^^^^^^^^^^^^^^^^
  File "C:\Users\NONE\Desktop\pythoN\jopa\.venv\Lib\site-packages\aiogram\dispatcher\router.py", line 146, in propagate_event
    return await observer.wrap_outer_middleware(_wrapped, event=event, data=kwargs)
           ^^^^^^^^^^^^^^^^^^^^^^^^^^^^^^^^^^^^^^^^^^^^^^^^^^^^^^^^^^^^^^^^^^^^^^^^
  File "C:\Users\NONE\Desktop\pythoN\jopa\.venv\Lib\site-packages\aiogram\dispatcher\router.py", line 141, in _wrapped
    return await self._propagate_event(
           ^^^^^^^^^^^^^^^^^^^^^^^^^^^^
  File "C:\Users\NONE\Desktop\pythoN\jopa\.venv\Lib\site-packages\aiogram\dispatcher\router.py", line 174, in _propagate_event
    response = await router.propagate_event(update_type=update_type, event=event, **kwargs)
               ^^^^^^^^^^^^^^^^^^^^^^^^^^^^^^^^^^^^^^^^^^^^^^^^^^^^^^^^^^^^^^^^^^^^^^^^^^^^
  File "C:\Users\NONE\Desktop\pythoN\jopa\.venv\Lib\site-packages\aiogram\dispatcher\router.py", line 146, in propagate_event
    return await observer.wrap_outer_middleware(_wrapped, event=event, data=kwargs)
           ^^^^^^^^^^^^^^^^^^^^^^^^^^^^^^^^^^^^^^^^^^^^^^^^^^^^^^^^^^^^^^^^^^^^^^^^
  File "C:\Users\NONE\Desktop\pythoN\jopa\.venv\Lib\site-packages\aiogram\dispatcher\router.py", line 141, in _wrapped
    return await self._propagate_event(
           ^^^^^^^^^^^^^^^^^^^^^^^^^^^^
  File "C:\Users\NONE\Desktop\pythoN\jopa\.venv\Lib\site-packages\aiogram\dispatcher\router.py", line 166, in _propagate_event
    response = await observer.trigger(event, **kwargs)
               ^^^^^^^^^^^^^^^^^^^^^^^^^^^^^^^^^^^^^^^
  File "C:\Users\NONE\Desktop\pythoN\jopa\.venv\Lib\site-packages\aiogram\dispatcher\event\telegram.py", line 121, in trigger
    return await wrapped_inner(event, kwargs)
           ^^^^^^^^^^^^^^^^^^^^^^^^^^^^^^^^^^
  File "C:\Users\NONE\Desktop\pythoN\jopa\.venv\Lib\site-packages\aiogram\dispatcher\event\handler.py", line 43, in call
    return await wrapped()
           ^^^^^^^^^^^^^^^
  File "C:\Users\NONE\Desktop\pythoN\jopa\bot\base.py", line 43, in sub_category
    article = await requests.select_sub_category(call.data)
              ^^^^^^^^^^^^^^^^^^^^^^^^^^^^^^^^^^^^^^^^^^^^^
  File "C:\Users\NONE\Desktop\pythoN\jopa\database\requests.py", line 28, in select_sub_category
    results = await session.execute(stmt)
              ^^^^^^^^^^^^^^^^^^^^^^^^^^^
  File "C:\Users\NONE\Desktop\pythoN\jopa\.venv\Lib\site-packages\sqlalchemy\ext\asyncio\session.py", line 461, in execute
    result = await greenlet_spawn(
             ^^^^^^^^^^^^^^^^^^^^^
  File "C:\Users\NONE\Desktop\pythoN\jopa\.venv\Lib\site-packages\sqlalchemy\util\_concurrency_py3k.py", line 201, in greenlet_spawn
    result = context.throw(*sys.exc_info())
             ^^^^^^^^^^^^^^^^^^^^^^^^^^^^^^
  File "C:\Users\NONE\Desktop\pythoN\jopa\.venv\Lib\site-packages\sqlalchemy\orm\session.py", line 2362, in execute
    return self._execute_internal(
           ^^^^^^^^^^^^^^^^^^^^^^^
  File "C:\Users\NONE\Desktop\pythoN\jopa\.venv\Lib\site-packages\sqlalchemy\orm\session.py", line 2247, in _execute_internal
    result: Result[Any] = compile_state_cls.orm_execute_statement(
                          ^^^^^^^^^^^^^^^^^^^^^^^^^^^^^^^^^^^^^^^^
  File "C:\Users\NONE\Desktop\pythoN\jopa\.venv\Lib\site-packages\sqlalchemy\orm\context.py", line 305, in orm_execute_statement
    result = conn.execute(
             ^^^^^^^^^^^^^
  File "C:\Users\NONE\Desktop\pythoN\jopa\.venv\Lib\site-packages\sqlalchemy\engine\base.py", line 1418, in execute
    return meth(
           ^^^^^
  File "C:\Users\NONE\Desktop\pythoN\jopa\.venv\Lib\site-packages\sqlalchemy\sql\elements.py", line 515, in _execute_on_connection
    return connection._execute_clauseelement(
           ^^^^^^^^^^^^^^^^^^^^^^^^^^^^^^^^^^
  File "C:\Users\NONE\Desktop\pythoN\jopa\.venv\Lib\site-packages\sqlalchemy\engine\base.py", line 1640, in _execute_clauseelement
    ret = self._execute_context(
          ^^^^^^^^^^^^^^^^^^^^^^
  File "C:\Users\NONE\Desktop\pythoN\jopa\.venv\Lib\site-packages\sqlalchemy\engine\base.py", line 1846, in _execute_context
    return self._exec_single_context(
           ^^^^^^^^^^^^^^^^^^^^^^^^^^
  File "C:\Users\NONE\Desktop\pythoN\jopa\.venv\Lib\site-packages\sqlalchemy\engine\base.py", line 1986, in _exec_single_context
    self._handle_dbapi_exception(
  File "C:\Users\NONE\Desktop\pythoN\jopa\.venv\Lib\site-packages\sqlalchemy\engine\base.py", line 2355, in _handle_dbapi_exception
    raise sqlalchemy_exception.with_traceback(exc_info[2]) from e
  File "C:\Users\NONE\Desktop\pythoN\jopa\.venv\Lib\site-packages\sqlalchemy\engine\base.py", line 1967, in _exec_single_context
    self.dialect.do_execute(
  File "C:\Users\NONE\Desktop\pythoN\jopa\.venv\Lib\site-packages\sqlalchemy\engine\default.py", line 941, in do_execute
    cursor.execute(statement, parameters)
  File "C:\Users\NONE\Desktop\pythoN\jopa\.venv\Lib\site-packages\sqlalchemy\dialects\postgresql\asyncpg.py", line 568, in execute
    self._adapt_connection.await_(
  File "C:\Users\NONE\Desktop\pythoN\jopa\.venv\Lib\site-packages\sqlalchemy\util\_concurrency_py3k.py", line 132, in await_only
    return current.parent.switch(awaitable)  # type: ignore[no-any-return,attr-defined] # noqa: E501
           ^^^^^^^^^^^^^^^^^^^^^^^^^^^^^^^^
  File "C:\Users\NONE\Desktop\pythoN\jopa\.venv\Lib\site-packages\sqlalchemy\util\_concurrency_py3k.py", line 196, in greenlet_spawn
    value = await result
            ^^^^^^^^^^^^
  File "C:\Users\NONE\Desktop\pythoN\jopa\.venv\Lib\site-packages\sqlalchemy\dialects\postgresql\asyncpg.py", line 546, in _prepare_and_execute
    self._handle_exception(error)
  File "C:\Users\NONE\Desktop\pythoN\jopa\.venv\Lib\site-packages\sqlalchemy\dialects\postgresql\asyncpg.py", line 497, in _handle_exception
    self._adapt_connection._handle_exception(error)
  File "C:\Users\NONE\Desktop\pythoN\jopa\.venv\Lib\site-packages\sqlalchemy\dialects\postgresql\asyncpg.py", line 780, in _handle_exception
    raise translated_error from error
sqlalchemy.exc.ProgrammingError: (sqlalchemy.dialects.postgresql.asyncpg.ProgrammingError) <class 'asyncpg.exceptions.UndefinedColumnError'>: column sub_category.departments does not exist
[SQL: SELECT sub_category.id, sub_category.name, sub_category.article, sub_category.departments 
FROM sub_category 
WHERE sub_category.article = $1::VARCHAR]
[parameters: ('M',)]
(Background on this error at: https://sqlalche.me/e/20/f405)
2024-10-20 14:37:38,957 [ ERROR  ] (dispatcher.py:_process_update:315): Cause exception while process update id=758780716 by bot id=8144851601
TypeError: can only concatenate str (not "int") to str
Traceback (most recent call last):
  File "C:\Users\NONE\Desktop\pythoN\jopa\.venv\Lib\site-packages\aiogram\dispatcher\dispatcher.py", line 309, in _process_update
    response = await self.feed_update(bot, update, **kwargs)
               ^^^^^^^^^^^^^^^^^^^^^^^^^^^^^^^^^^^^^^^^^^^^^
  File "C:\Users\NONE\Desktop\pythoN\jopa\.venv\Lib\site-packages\aiogram\dispatcher\dispatcher.py", line 158, in feed_update
    response = await self.update.wrap_outer_middleware(
               ^^^^^^^^^^^^^^^^^^^^^^^^^^^^^^^^^^^^^^^^
  File "C:\Users\NONE\Desktop\pythoN\jopa\.venv\Lib\site-packages\aiogram\dispatcher\middlewares\error.py", line 25, in __call__
    return await handler(event, data)
           ^^^^^^^^^^^^^^^^^^^^^^^^^^
  File "C:\Users\NONE\Desktop\pythoN\jopa\.venv\Lib\site-packages\aiogram\dispatcher\middlewares\user_context.py", line 56, in __call__
    return await handler(event, data)
           ^^^^^^^^^^^^^^^^^^^^^^^^^^
  File "C:\Users\NONE\AppData\Local\Programs\Python\Python311\Lib\contextlib.py", line 222, in __aexit__
    await self.gen.athrow(typ, value, traceback)
  File "C:\Users\NONE\Desktop\pythoN\jopa\.venv\Lib\site-packages\aiogram\fsm\storage\memory.py", line 56, in lock
    yield
  File "C:\Users\NONE\Desktop\pythoN\jopa\.venv\Lib\site-packages\aiogram\fsm\middleware.py", line 42, in __call__
    return await handler(event, data)
           ^^^^^^^^^^^^^^^^^^^^^^^^^^
  File "C:\Users\NONE\Desktop\pythoN\jopa\.venv\Lib\site-packages\aiogram\dispatcher\event\telegram.py", line 121, in trigger
    return await wrapped_inner(event, kwargs)
           ^^^^^^^^^^^^^^^^^^^^^^^^^^^^^^^^^^
  File "C:\Users\NONE\Desktop\pythoN\jopa\.venv\Lib\site-packages\aiogram\dispatcher\event\handler.py", line 43, in call
    return await wrapped()
           ^^^^^^^^^^^^^^^
  File "C:\Users\NONE\Desktop\pythoN\jopa\.venv\Lib\site-packages\aiogram\dispatcher\dispatcher.py", line 276, in _listen_update
    return await self.propagate_event(update_type=update_type, event=event, **kwargs)
           ^^^^^^^^^^^^^^^^^^^^^^^^^^^^^^^^^^^^^^^^^^^^^^^^^^^^^^^^^^^^^^^^^^^^^^^^^^
  File "C:\Users\NONE\Desktop\pythoN\jopa\.venv\Lib\site-packages\aiogram\dispatcher\router.py", line 146, in propagate_event
    return await observer.wrap_outer_middleware(_wrapped, event=event, data=kwargs)
           ^^^^^^^^^^^^^^^^^^^^^^^^^^^^^^^^^^^^^^^^^^^^^^^^^^^^^^^^^^^^^^^^^^^^^^^^
  File "C:\Users\NONE\Desktop\pythoN\jopa\.venv\Lib\site-packages\aiogram\dispatcher\router.py", line 141, in _wrapped
    return await self._propagate_event(
           ^^^^^^^^^^^^^^^^^^^^^^^^^^^^
  File "C:\Users\NONE\Desktop\pythoN\jopa\.venv\Lib\site-packages\aiogram\dispatcher\router.py", line 174, in _propagate_event
    response = await router.propagate_event(update_type=update_type, event=event, **kwargs)
               ^^^^^^^^^^^^^^^^^^^^^^^^^^^^^^^^^^^^^^^^^^^^^^^^^^^^^^^^^^^^^^^^^^^^^^^^^^^^
  File "C:\Users\NONE\Desktop\pythoN\jopa\.venv\Lib\site-packages\aiogram\dispatcher\router.py", line 146, in propagate_event
    return await observer.wrap_outer_middleware(_wrapped, event=event, data=kwargs)
           ^^^^^^^^^^^^^^^^^^^^^^^^^^^^^^^^^^^^^^^^^^^^^^^^^^^^^^^^^^^^^^^^^^^^^^^^
  File "C:\Users\NONE\Desktop\pythoN\jopa\.venv\Lib\site-packages\aiogram\dispatcher\router.py", line 141, in _wrapped
    return await self._propagate_event(
           ^^^^^^^^^^^^^^^^^^^^^^^^^^^^
  File "C:\Users\NONE\Desktop\pythoN\jopa\.venv\Lib\site-packages\aiogram\dispatcher\router.py", line 166, in _propagate_event
    response = await observer.trigger(event, **kwargs)
               ^^^^^^^^^^^^^^^^^^^^^^^^^^^^^^^^^^^^^^^
  File "C:\Users\NONE\Desktop\pythoN\jopa\.venv\Lib\site-packages\aiogram\dispatcher\event\telegram.py", line 121, in trigger
    return await wrapped_inner(event, kwargs)
           ^^^^^^^^^^^^^^^^^^^^^^^^^^^^^^^^^^
  File "C:\Users\NONE\Desktop\pythoN\jopa\.venv\Lib\site-packages\aiogram\dispatcher\event\handler.py", line 43, in call
    return await wrapped()
           ^^^^^^^^^^^^^^^
  File "C:\Users\NONE\Desktop\pythoN\jopa\bot\base.py", line 44, in sub_category
    await call.message.edit_text("Выберите желаемую ПОД-категорию: ", reply_markup=kb.sub_category(article))
                                                                                   ^^^^^^^^^^^^^^^^^^^^^^^^
  File "C:\Users\NONE\Desktop\pythoN\jopa\bot\kb.py", line 45, in sub_category
    category_id = 'category' + category.id
                  ~~~~~~~~~~~^~~~~~~~~~~~~
TypeError: can only concatenate str (not "int") to str
2024-10-20 14:39:33,245 [CRITICAL] (main.py:bot_start:18): Error: 
Traceback (most recent call last):
  File "C:\Users\NONE\Desktop\pythoN\jopa\main.py", line 15, in bot_start
    await dp.start_polling(bot)
  File "C:\Users\NONE\Desktop\pythoN\jopa\.venv\Lib\site-packages\aiogram\dispatcher\dispatcher.py", line 543, in start_polling
    done, pending = await asyncio.wait(tasks, return_when=asyncio.FIRST_COMPLETED)
                    ^^^^^^^^^^^^^^^^^^^^^^^^^^^^^^^^^^^^^^^^^^^^^^^^^^^^^^^^^^^^^^
  File "C:\Users\NONE\AppData\Local\Programs\Python\Python311\Lib\asyncio\tasks.py", line 418, in wait
    return await _wait(fs, timeout, return_when, loop)
           ^^^^^^^^^^^^^^^^^^^^^^^^^^^^^^^^^^^^^^^^^^^
  File "C:\Users\NONE\AppData\Local\Programs\Python\Python311\Lib\asyncio\tasks.py", line 525, in _wait
    await waiter
asyncio.exceptions.CancelledError
2024-10-20 14:39:33,250 [CRITICAL] (main.py:main:26): Error: 
Traceback (most recent call last):
  File "C:\Users\NONE\Desktop\pythoN\jopa\main.py", line 24, in main
    await asyncio.gather(bot_app, db_app)
asyncio.exceptions.CancelledError
2024-10-20 15:28:27,744 [ ERROR  ] (dispatcher.py:_process_update:315): Cause exception while process update id=758780771 by bot id=8144851601
InterfaceError: (sqlalchemy.dialects.postgresql.asyncpg.InterfaceError) <class 'asyncpg.exceptions._base.InterfaceError'>: connection is closed
[SQL: SELECT sub_category.id, sub_category.name, sub_category.article 
FROM sub_category 
WHERE sub_category.article = $1::VARCHAR]
[parameters: ('M',)]
(Background on this error at: https://sqlalche.me/e/20/rvf5)
Traceback (most recent call last):
  File "C:\Users\NONE\Desktop\pythoN\jopa\.venv\Lib\site-packages\sqlalchemy\dialects\postgresql\asyncpg.py", line 826, in _start_transaction
    self._transaction = self._connection.transaction(
                        ^^^^^^^^^^^^^^^^^^^^^^^^^^^^^
  File "C:\Users\NONE\Desktop\pythoN\jopa\.venv\Lib\site-packages\asyncpg\connection.py", line 303, in transaction
    self._check_open()
  File "C:\Users\NONE\Desktop\pythoN\jopa\.venv\Lib\site-packages\asyncpg\connection.py", line 1534, in _check_open
    raise exceptions.InterfaceError('connection is closed')
asyncpg.exceptions._base.InterfaceError: connection is closed

The above exception was the direct cause of the following exception:

Traceback (most recent call last):
  File "C:\Users\NONE\Desktop\pythoN\jopa\.venv\Lib\site-packages\sqlalchemy\engine\base.py", line 1967, in _exec_single_context
    self.dialect.do_execute(
  File "C:\Users\NONE\Desktop\pythoN\jopa\.venv\Lib\site-packages\sqlalchemy\engine\default.py", line 941, in do_execute
    cursor.execute(statement, parameters)
  File "C:\Users\NONE\Desktop\pythoN\jopa\.venv\Lib\site-packages\sqlalchemy\dialects\postgresql\asyncpg.py", line 568, in execute
    self._adapt_connection.await_(
  File "C:\Users\NONE\Desktop\pythoN\jopa\.venv\Lib\site-packages\sqlalchemy\util\_concurrency_py3k.py", line 132, in await_only
    return current.parent.switch(awaitable)  # type: ignore[no-any-return,attr-defined] # noqa: E501
           ^^^^^^^^^^^^^^^^^^^^^^^^^^^^^^^^
  File "C:\Users\NONE\Desktop\pythoN\jopa\.venv\Lib\site-packages\sqlalchemy\util\_concurrency_py3k.py", line 196, in greenlet_spawn
    value = await result
            ^^^^^^^^^^^^
  File "C:\Users\NONE\Desktop\pythoN\jopa\.venv\Lib\site-packages\sqlalchemy\dialects\postgresql\asyncpg.py", line 504, in _prepare_and_execute
    await adapt_connection._start_transaction()
  File "C:\Users\NONE\Desktop\pythoN\jopa\.venv\Lib\site-packages\sqlalchemy\dialects\postgresql\asyncpg.py", line 833, in _start_transaction
    self._handle_exception(error)
  File "C:\Users\NONE\Desktop\pythoN\jopa\.venv\Lib\site-packages\sqlalchemy\dialects\postgresql\asyncpg.py", line 780, in _handle_exception
    raise translated_error from error
sqlalchemy.dialects.postgresql.asyncpg.AsyncAdapt_asyncpg_dbapi.InterfaceError: <class 'asyncpg.exceptions._base.InterfaceError'>: connection is closed

The above exception was the direct cause of the following exception:

Traceback (most recent call last):
  File "C:\Users\NONE\Desktop\pythoN\jopa\.venv\Lib\site-packages\aiogram\dispatcher\dispatcher.py", line 309, in _process_update
    response = await self.feed_update(bot, update, **kwargs)
               ^^^^^^^^^^^^^^^^^^^^^^^^^^^^^^^^^^^^^^^^^^^^^
  File "C:\Users\NONE\Desktop\pythoN\jopa\.venv\Lib\site-packages\aiogram\dispatcher\dispatcher.py", line 158, in feed_update
    response = await self.update.wrap_outer_middleware(
               ^^^^^^^^^^^^^^^^^^^^^^^^^^^^^^^^^^^^^^^^
  File "C:\Users\NONE\Desktop\pythoN\jopa\.venv\Lib\site-packages\aiogram\dispatcher\middlewares\error.py", line 25, in __call__
    return await handler(event, data)
           ^^^^^^^^^^^^^^^^^^^^^^^^^^
  File "C:\Users\NONE\Desktop\pythoN\jopa\.venv\Lib\site-packages\aiogram\dispatcher\middlewares\user_context.py", line 56, in __call__
    return await handler(event, data)
           ^^^^^^^^^^^^^^^^^^^^^^^^^^
  File "C:\Users\NONE\AppData\Local\Programs\Python\Python311\Lib\contextlib.py", line 222, in __aexit__
    await self.gen.athrow(typ, value, traceback)
  File "C:\Users\NONE\Desktop\pythoN\jopa\.venv\Lib\site-packages\aiogram\fsm\storage\memory.py", line 56, in lock
    yield
  File "C:\Users\NONE\Desktop\pythoN\jopa\.venv\Lib\site-packages\aiogram\fsm\middleware.py", line 42, in __call__
    return await handler(event, data)
           ^^^^^^^^^^^^^^^^^^^^^^^^^^
  File "C:\Users\NONE\Desktop\pythoN\jopa\.venv\Lib\site-packages\aiogram\dispatcher\event\telegram.py", line 121, in trigger
    return await wrapped_inner(event, kwargs)
           ^^^^^^^^^^^^^^^^^^^^^^^^^^^^^^^^^^
  File "C:\Users\NONE\Desktop\pythoN\jopa\.venv\Lib\site-packages\aiogram\dispatcher\event\handler.py", line 43, in call
    return await wrapped()
           ^^^^^^^^^^^^^^^
  File "C:\Users\NONE\Desktop\pythoN\jopa\.venv\Lib\site-packages\aiogram\dispatcher\dispatcher.py", line 276, in _listen_update
    return await self.propagate_event(update_type=update_type, event=event, **kwargs)
           ^^^^^^^^^^^^^^^^^^^^^^^^^^^^^^^^^^^^^^^^^^^^^^^^^^^^^^^^^^^^^^^^^^^^^^^^^^
  File "C:\Users\NONE\Desktop\pythoN\jopa\.venv\Lib\site-packages\aiogram\dispatcher\router.py", line 146, in propagate_event
    return await observer.wrap_outer_middleware(_wrapped, event=event, data=kwargs)
           ^^^^^^^^^^^^^^^^^^^^^^^^^^^^^^^^^^^^^^^^^^^^^^^^^^^^^^^^^^^^^^^^^^^^^^^^
  File "C:\Users\NONE\Desktop\pythoN\jopa\.venv\Lib\site-packages\aiogram\dispatcher\router.py", line 141, in _wrapped
    return await self._propagate_event(
           ^^^^^^^^^^^^^^^^^^^^^^^^^^^^
  File "C:\Users\NONE\Desktop\pythoN\jopa\.venv\Lib\site-packages\aiogram\dispatcher\router.py", line 174, in _propagate_event
    response = await router.propagate_event(update_type=update_type, event=event, **kwargs)
               ^^^^^^^^^^^^^^^^^^^^^^^^^^^^^^^^^^^^^^^^^^^^^^^^^^^^^^^^^^^^^^^^^^^^^^^^^^^^
  File "C:\Users\NONE\Desktop\pythoN\jopa\.venv\Lib\site-packages\aiogram\dispatcher\router.py", line 146, in propagate_event
    return await observer.wrap_outer_middleware(_wrapped, event=event, data=kwargs)
           ^^^^^^^^^^^^^^^^^^^^^^^^^^^^^^^^^^^^^^^^^^^^^^^^^^^^^^^^^^^^^^^^^^^^^^^^
  File "C:\Users\NONE\Desktop\pythoN\jopa\.venv\Lib\site-packages\aiogram\dispatcher\router.py", line 141, in _wrapped
    return await self._propagate_event(
           ^^^^^^^^^^^^^^^^^^^^^^^^^^^^
  File "C:\Users\NONE\Desktop\pythoN\jopa\.venv\Lib\site-packages\aiogram\dispatcher\router.py", line 166, in _propagate_event
    response = await observer.trigger(event, **kwargs)
               ^^^^^^^^^^^^^^^^^^^^^^^^^^^^^^^^^^^^^^^
  File "C:\Users\NONE\Desktop\pythoN\jopa\.venv\Lib\site-packages\aiogram\dispatcher\event\telegram.py", line 121, in trigger
    return await wrapped_inner(event, kwargs)
           ^^^^^^^^^^^^^^^^^^^^^^^^^^^^^^^^^^
  File "C:\Users\NONE\Desktop\pythoN\jopa\.venv\Lib\site-packages\aiogram\dispatcher\event\handler.py", line 43, in call
    return await wrapped()
           ^^^^^^^^^^^^^^^
  File "C:\Users\NONE\Desktop\pythoN\jopa\bot\base.py", line 43, in sub_category
    await call.message.edit_text("Выберите желаемую категорию: ", reply_markup=kb.category())
                  
  File "C:\Users\NONE\Desktop\pythoN\jopa\database\requests.py", line 28, in select_sub_category
    results = await session.execute(stmt)
              ^^^^^^^^^^^^^^^^^^^^^^^^^^^
  File "C:\Users\NONE\Desktop\pythoN\jopa\.venv\Lib\site-packages\sqlalchemy\ext\asyncio\session.py", line 461, in execute
    result = await greenlet_spawn(
             ^^^^^^^^^^^^^^^^^^^^^
  File "C:\Users\NONE\Desktop\pythoN\jopa\.venv\Lib\site-packages\sqlalchemy\util\_concurrency_py3k.py", line 203, in greenlet_spawn
    result = context.switch(value)
             ^^^^^^^^^^^^^^^^^^^^^
  File "C:\Users\NONE\Desktop\pythoN\jopa\.venv\Lib\site-packages\sqlalchemy\orm\session.py", line 2362, in execute
    return self._execute_internal(
           ^^^^^^^^^^^^^^^^^^^^^^^
  File "C:\Users\NONE\Desktop\pythoN\jopa\.venv\Lib\site-packages\sqlalchemy\orm\session.py", line 2247, in _execute_internal
    result: Result[Any] = compile_state_cls.orm_execute_statement(
                          ^^^^^^^^^^^^^^^^^^^^^^^^^^^^^^^^^^^^^^^^
  File "C:\Users\NONE\Desktop\pythoN\jopa\.venv\Lib\site-packages\sqlalchemy\orm\context.py", line 305, in orm_execute_statement
    result = conn.execute(
             ^^^^^^^^^^^^^
  File "C:\Users\NONE\Desktop\pythoN\jopa\.venv\Lib\site-packages\sqlalchemy\engine\base.py", line 1418, in execute
    return meth(
           ^^^^^
  File "C:\Users\NONE\Desktop\pythoN\jopa\.venv\Lib\site-packages\sqlalchemy\sql\elements.py", line 515, in _execute_on_connection
    return connection._execute_clauseelement(
           ^^^^^^^^^^^^^^^^^^^^^^^^^^^^^^^^^^
  File "C:\Users\NONE\Desktop\pythoN\jopa\.venv\Lib\site-packages\sqlalchemy\engine\base.py", line 1640, in _execute_clauseelement
    ret = self._execute_context(
          ^^^^^^^^^^^^^^^^^^^^^^
  File "C:\Users\NONE\Desktop\pythoN\jopa\.venv\Lib\site-packages\sqlalchemy\engine\base.py", line 1846, in _execute_context
    return self._exec_single_context(
           ^^^^^^^^^^^^^^^^^^^^^^^^^^
  File "C:\Users\NONE\Desktop\pythoN\jopa\.venv\Lib\site-packages\sqlalchemy\engine\base.py", line 1986, in _exec_single_context
    self._handle_dbapi_exception(
  File "C:\Users\NONE\Desktop\pythoN\jopa\.venv\Lib\site-packages\sqlalchemy\engine\base.py", line 2355, in _handle_dbapi_exception
    raise sqlalchemy_exception.with_traceback(exc_info[2]) from e
  File "C:\Users\NONE\Desktop\pythoN\jopa\.venv\Lib\site-packages\sqlalchemy\engine\base.py", line 1967, in _exec_single_context
    self.dialect.do_execute(
  File "C:\Users\NONE\Desktop\pythoN\jopa\.venv\Lib\site-packages\sqlalchemy\engine\default.py", line 941, in do_execute
    cursor.execute(statement, parameters)
  File "C:\Users\NONE\Desktop\pythoN\jopa\.venv\Lib\site-packages\sqlalchemy\dialects\postgresql\asyncpg.py", line 568, in execute
    self._adapt_connection.await_(
  File "C:\Users\NONE\Desktop\pythoN\jopa\.venv\Lib\site-packages\sqlalchemy\util\_concurrency_py3k.py", line 132, in await_only
    return current.parent.switch(awaitable)  # type: ignore[no-any-return,attr-defined] # noqa: E501
           ^^^^^^^^^^^^^^^^^^^^^^^^^^^^^^^^
  File "C:\Users\NONE\Desktop\pythoN\jopa\.venv\Lib\site-packages\sqlalchemy\util\_concurrency_py3k.py", line 196, in greenlet_spawn
    value = await result
            ^^^^^^^^^^^^
  File "C:\Users\NONE\Desktop\pythoN\jopa\.venv\Lib\site-packages\sqlalchemy\dialects\postgresql\asyncpg.py", line 504, in _prepare_and_execute
    await adapt_connection._start_transaction()
  File "C:\Users\NONE\Desktop\pythoN\jopa\.venv\Lib\site-packages\sqlalchemy\dialects\postgresql\asyncpg.py", line 833, in _start_transaction
    self._handle_exception(error)
  File "C:\Users\NONE\Desktop\pythoN\jopa\.venv\Lib\site-packages\sqlalchemy\dialects\postgresql\asyncpg.py", line 780, in _handle_exception
    raise translated_error from error
sqlalchemy.exc.InterfaceError: (sqlalchemy.dialects.postgresql.asyncpg.InterfaceError) <class 'asyncpg.exceptions._base.InterfaceError'>: connection is closed
[SQL: SELECT sub_category.id, sub_category.name, sub_category.article 
FROM sub_category 
WHERE sub_category.article = $1::VARCHAR]
[parameters: ('M',)]
(Background on this error at: https://sqlalche.me/e/20/rvf5)
2024-10-20 15:45:45,623 [ ERROR  ] (dispatcher.py:_process_update:315): Cause exception while process update id=758780796 by bot id=8144851601
KeyError: 'code'
Traceback (most recent call last):
  File "C:\Users\NONE\Desktop\pythoN\jopa\.venv\Lib\site-packages\aiogram\dispatcher\dispatcher.py", line 309, in _process_update
    response = await self.feed_update(bot, update, **kwargs)
               ^^^^^^^^^^^^^^^^^^^^^^^^^^^^^^^^^^^^^^^^^^^^^
  File "C:\Users\NONE\Desktop\pythoN\jopa\.venv\Lib\site-packages\aiogram\dispatcher\dispatcher.py", line 158, in feed_update
    response = await self.update.wrap_outer_middleware(
               ^^^^^^^^^^^^^^^^^^^^^^^^^^^^^^^^^^^^^^^^
  File "C:\Users\NONE\Desktop\pythoN\jopa\.venv\Lib\site-packages\aiogram\dispatcher\middlewares\error.py", line 25, in __call__
    return await handler(event, data)
           ^^^^^^^^^^^^^^^^^^^^^^^^^^
  File "C:\Users\NONE\Desktop\pythoN\jopa\.venv\Lib\site-packages\aiogram\dispatcher\middlewares\user_context.py", line 56, in __call__
    return await handler(event, data)
           ^^^^^^^^^^^^^^^^^^^^^^^^^^
  File "C:\Users\NONE\AppData\Local\Programs\Python\Python311\Lib\contextlib.py", line 222, in __aexit__
    await self.gen.athrow(typ, value, traceback)
  File "C:\Users\NONE\Desktop\pythoN\jopa\.venv\Lib\site-packages\aiogram\fsm\storage\memory.py", line 56, in lock
    yield
  File "C:\Users\NONE\Desktop\pythoN\jopa\.venv\Lib\site-packages\aiogram\fsm\middleware.py", line 42, in __call__
    return await handler(event, data)
           ^^^^^^^^^^^^^^^^^^^^^^^^^^
  File "C:\Users\NONE\Desktop\pythoN\jopa\.venv\Lib\site-packages\aiogram\dispatcher\event\telegram.py", line 121, in trigger
    return await wrapped_inner(event, kwargs)
           ^^^^^^^^^^^^^^^^^^^^^^^^^^^^^^^^^^
  File "C:\Users\NONE\Desktop\pythoN\jopa\.venv\Lib\site-packages\aiogram\dispatcher\event\handler.py", line 43, in call
    return await wrapped()
           ^^^^^^^^^^^^^^^
  File "C:\Users\NONE\Desktop\pythoN\jopa\.venv\Lib\site-packages\aiogram\dispatcher\dispatcher.py", line 276, in _listen_update
    return await self.propagate_event(update_type=update_type, event=event, **kwargs)
           ^^^^^^^^^^^^^^^^^^^^^^^^^^^^^^^^^^^^^^^^^^^^^^^^^^^^^^^^^^^^^^^^^^^^^^^^^^
  File "C:\Users\NONE\Desktop\pythoN\jopa\.venv\Lib\site-packages\aiogram\dispatcher\router.py", line 146, in propagate_event
    return await observer.wrap_outer_middleware(_wrapped, event=event, data=kwargs)
           ^^^^^^^^^^^^^^^^^^^^^^^^^^^^^^^^^^^^^^^^^^^^^^^^^^^^^^^^^^^^^^^^^^^^^^^^
  File "C:\Users\NONE\Desktop\pythoN\jopa\.venv\Lib\site-packages\aiogram\dispatcher\router.py", line 141, in _wrapped
    return await self._propagate_event(
           ^^^^^^^^^^^^^^^^^^^^^^^^^^^^
  File "C:\Users\NONE\Desktop\pythoN\jopa\.venv\Lib\site-packages\aiogram\dispatcher\router.py", line 174, in _propagate_event
    response = await router.propagate_event(update_type=update_type, event=event, **kwargs)
               ^^^^^^^^^^^^^^^^^^^^^^^^^^^^^^^^^^^^^^^^^^^^^^^^^^^^^^^^^^^^^^^^^^^^^^^^^^^^
  File "C:\Users\NONE\Desktop\pythoN\jopa\.venv\Lib\site-packages\aiogram\dispatcher\router.py", line 146, in propagate_event
    return await observer.wrap_outer_middleware(_wrapped, event=event, data=kwargs)
           ^^^^^^^^^^^^^^^^^^^^^^^^^^^^^^^^^^^^^^^^^^^^^^^^^^^^^^^^^^^^^^^^^^^^^^^^
  File "C:\Users\NONE\Desktop\pythoN\jopa\.venv\Lib\site-packages\aiogram\dispatcher\router.py", line 141, in _wrapped
    return await self._propagate_event(
           ^^^^^^^^^^^^^^^^^^^^^^^^^^^^
  File "C:\Users\NONE\Desktop\pythoN\jopa\.venv\Lib\site-packages\aiogram\dispatcher\router.py", line 166, in _propagate_event
    response = await observer.trigger(event, **kwargs)
               ^^^^^^^^^^^^^^^^^^^^^^^^^^^^^^^^^^^^^^^
  File "C:\Users\NONE\Desktop\pythoN\jopa\.venv\Lib\site-packages\aiogram\dispatcher\event\telegram.py", line 121, in trigger
    return await wrapped_inner(event, kwargs)
           ^^^^^^^^^^^^^^^^^^^^^^^^^^^^^^^^^^
  File "C:\Users\NONE\Desktop\pythoN\jopa\.venv\Lib\site-packages\aiogram\dispatcher\event\handler.py", line 43, in call
    return await wrapped()
           ^^^^^^^^^^^^^^^
  File "C:\Users\NONE\Desktop\pythoN\jopa\bot\base.py", line 79, in check
    name = data["code"]
           ~~~~^^^^^^^^
KeyError: 'code'
2024-10-20 15:46:39,677 [ ERROR  ] (dispatcher.py:_process_update:315): Cause exception while process update id=758780797 by bot id=8144851601
KeyError: 'name'
Traceback (most recent call last):
  File "C:\Users\NONE\Desktop\pythoN\jopa\.venv\Lib\site-packages\aiogram\dispatcher\dispatcher.py", line 309, in _process_update
    response = await self.feed_update(bot, update, **kwargs)
               ^^^^^^^^^^^^^^^^^^^^^^^^^^^^^^^^^^^^^^^^^^^^^
  File "C:\Users\NONE\Desktop\pythoN\jopa\.venv\Lib\site-packages\aiogram\dispatcher\dispatcher.py", line 158, in feed_update
    response = await self.update.wrap_outer_middleware(
               ^^^^^^^^^^^^^^^^^^^^^^^^^^^^^^^^^^^^^^^^
  File "C:\Users\NONE\Desktop\pythoN\jopa\.venv\Lib\site-packages\aiogram\dispatcher\middlewares\error.py", line 25, in __call__
    return await handler(event, data)
           ^^^^^^^^^^^^^^^^^^^^^^^^^^
  File "C:\Users\NONE\Desktop\pythoN\jopa\.venv\Lib\site-packages\aiogram\dispatcher\middlewares\user_context.py", line 56, in __call__
    return await handler(event, data)
           ^^^^^^^^^^^^^^^^^^^^^^^^^^
  File "C:\Users\NONE\AppData\Local\Programs\Python\Python311\Lib\contextlib.py", line 222, in __aexit__
    await self.gen.athrow(typ, value, traceback)
  File "C:\Users\NONE\Desktop\pythoN\jopa\.venv\Lib\site-packages\aiogram\fsm\storage\memory.py", line 56, in lock
    yield
  File "C:\Users\NONE\Desktop\pythoN\jopa\.venv\Lib\site-packages\aiogram\fsm\middleware.py", line 42, in __call__
    return await handler(event, data)
           ^^^^^^^^^^^^^^^^^^^^^^^^^^
  File "C:\Users\NONE\Desktop\pythoN\jopa\.venv\Lib\site-packages\aiogram\dispatcher\event\telegram.py", line 121, in trigger
    return await wrapped_inner(event, kwargs)
           ^^^^^^^^^^^^^^^^^^^^^^^^^^^^^^^^^^
  File "C:\Users\NONE\Desktop\pythoN\jopa\.venv\Lib\site-packages\aiogram\dispatcher\event\handler.py", line 43, in call
    return await wrapped()
           ^^^^^^^^^^^^^^^
  File "C:\Users\NONE\Desktop\pythoN\jopa\.venv\Lib\site-packages\aiogram\dispatcher\dispatcher.py", line 276, in _listen_update
    return await self.propagate_event(update_type=update_type, event=event, **kwargs)
           ^^^^^^^^^^^^^^^^^^^^^^^^^^^^^^^^^^^^^^^^^^^^^^^^^^^^^^^^^^^^^^^^^^^^^^^^^^
  File "C:\Users\NONE\Desktop\pythoN\jopa\.venv\Lib\site-packages\aiogram\dispatcher\router.py", line 146, in propagate_event
    return await observer.wrap_outer_middleware(_wrapped, event=event, data=kwargs)
           ^^^^^^^^^^^^^^^^^^^^^^^^^^^^^^^^^^^^^^^^^^^^^^^^^^^^^^^^^^^^^^^^^^^^^^^^
  File "C:\Users\NONE\Desktop\pythoN\jopa\.venv\Lib\site-packages\aiogram\dispatcher\router.py", line 141, in _wrapped
    return await self._propagate_event(
           ^^^^^^^^^^^^^^^^^^^^^^^^^^^^
  File "C:\Users\NONE\Desktop\pythoN\jopa\.venv\Lib\site-packages\aiogram\dispatcher\router.py", line 174, in _propagate_event
    response = await router.propagate_event(update_type=update_type, event=event, **kwargs)
               ^^^^^^^^^^^^^^^^^^^^^^^^^^^^^^^^^^^^^^^^^^^^^^^^^^^^^^^^^^^^^^^^^^^^^^^^^^^^
  File "C:\Users\NONE\Desktop\pythoN\jopa\.venv\Lib\site-packages\aiogram\dispatcher\router.py", line 146, in propagate_event
    return await observer.wrap_outer_middleware(_wrapped, event=event, data=kwargs)
           ^^^^^^^^^^^^^^^^^^^^^^^^^^^^^^^^^^^^^^^^^^^^^^^^^^^^^^^^^^^^^^^^^^^^^^^^
  File "C:\Users\NONE\Desktop\pythoN\jopa\.venv\Lib\site-packages\aiogram\dispatcher\router.py", line 141, in _wrapped
    return await self._propagate_event(
           ^^^^^^^^^^^^^^^^^^^^^^^^^^^^
  File "C:\Users\NONE\Desktop\pythoN\jopa\.venv\Lib\site-packages\aiogram\dispatcher\router.py", line 166, in _propagate_event
    response = await observer.trigger(event, **kwargs)
               ^^^^^^^^^^^^^^^^^^^^^^^^^^^^^^^^^^^^^^^
  File "C:\Users\NONE\Desktop\pythoN\jopa\.venv\Lib\site-packages\aiogram\dispatcher\event\telegram.py", line 121, in trigger
    return await wrapped_inner(event, kwargs)
           ^^^^^^^^^^^^^^^^^^^^^^^^^^^^^^^^^^
  File "C:\Users\NONE\Desktop\pythoN\jopa\.venv\Lib\site-packages\aiogram\dispatcher\event\handler.py", line 43, in call
    return await wrapped()
           ^^^^^^^^^^^^^^^
  File "C:\Users\NONE\Desktop\pythoN\jopa\bot\base.py", line 79, in check
    name = data["name"]
           ~~~~^^^^^^^^
KeyError: 'name'
2024-10-20 15:47:22,003 [ ERROR  ] (dispatcher.py:_process_update:315): Cause exception while process update id=758780803 by bot id=8144851601
KeyError: 'name'
Traceback (most recent call last):
  File "C:\Users\NONE\Desktop\pythoN\jopa\.venv\Lib\site-packages\aiogram\dispatcher\dispatcher.py", line 309, in _process_update
    response = await self.feed_update(bot, update, **kwargs)
               ^^^^^^^^^^^^^^^^^^^^^^^^^^^^^^^^^^^^^^^^^^^^^
  File "C:\Users\NONE\Desktop\pythoN\jopa\.venv\Lib\site-packages\aiogram\dispatcher\dispatcher.py", line 158, in feed_update
    response = await self.update.wrap_outer_middleware(
               ^^^^^^^^^^^^^^^^^^^^^^^^^^^^^^^^^^^^^^^^
  File "C:\Users\NONE\Desktop\pythoN\jopa\.venv\Lib\site-packages\aiogram\dispatcher\middlewares\error.py", line 25, in __call__
    return await handler(event, data)
           ^^^^^^^^^^^^^^^^^^^^^^^^^^
  File "C:\Users\NONE\Desktop\pythoN\jopa\.venv\Lib\site-packages\aiogram\dispatcher\middlewares\user_context.py", line 56, in __call__
    return await handler(event, data)
           ^^^^^^^^^^^^^^^^^^^^^^^^^^
  File "C:\Users\NONE\AppData\Local\Programs\Python\Python311\Lib\contextlib.py", line 222, in __aexit__
    await self.gen.athrow(typ, value, traceback)
  File "C:\Users\NONE\Desktop\pythoN\jopa\.venv\Lib\site-packages\aiogram\fsm\storage\memory.py", line 56, in lock
    yield
  File "C:\Users\NONE\Desktop\pythoN\jopa\.venv\Lib\site-packages\aiogram\fsm\middleware.py", line 42, in __call__
    return await handler(event, data)
           ^^^^^^^^^^^^^^^^^^^^^^^^^^
  File "C:\Users\NONE\Desktop\pythoN\jopa\.venv\Lib\site-packages\aiogram\dispatcher\event\telegram.py", line 121, in trigger
    return await wrapped_inner(event, kwargs)
           ^^^^^^^^^^^^^^^^^^^^^^^^^^^^^^^^^^
  File "C:\Users\NONE\Desktop\pythoN\jopa\.venv\Lib\site-packages\aiogram\dispatcher\event\handler.py", line 43, in call
    return await wrapped()
           ^^^^^^^^^^^^^^^
  File "C:\Users\NONE\Desktop\pythoN\jopa\.venv\Lib\site-packages\aiogram\dispatcher\dispatcher.py", line 276, in _listen_update
    return await self.propagate_event(update_type=update_type, event=event, **kwargs)
           ^^^^^^^^^^^^^^^^^^^^^^^^^^^^^^^^^^^^^^^^^^^^^^^^^^^^^^^^^^^^^^^^^^^^^^^^^^
  File "C:\Users\NONE\Desktop\pythoN\jopa\.venv\Lib\site-packages\aiogram\dispatcher\router.py", line 146, in propagate_event
    return await observer.wrap_outer_middleware(_wrapped, event=event, data=kwargs)
           ^^^^^^^^^^^^^^^^^^^^^^^^^^^^^^^^^^^^^^^^^^^^^^^^^^^^^^^^^^^^^^^^^^^^^^^^
  File "C:\Users\NONE\Desktop\pythoN\jopa\.venv\Lib\site-packages\aiogram\dispatcher\router.py", line 141, in _wrapped
    return await self._propagate_event(
           ^^^^^^^^^^^^^^^^^^^^^^^^^^^^
  File "C:\Users\NONE\Desktop\pythoN\jopa\.venv\Lib\site-packages\aiogram\dispatcher\router.py", line 174, in _propagate_event
    response = await router.propagate_event(update_type=update_type, event=event, **kwargs)
               ^^^^^^^^^^^^^^^^^^^^^^^^^^^^^^^^^^^^^^^^^^^^^^^^^^^^^^^^^^^^^^^^^^^^^^^^^^^^
  File "C:\Users\NONE\Desktop\pythoN\jopa\.venv\Lib\site-packages\aiogram\dispatcher\router.py", line 146, in propagate_event
    return await observer.wrap_outer_middleware(_wrapped, event=event, data=kwargs)
           ^^^^^^^^^^^^^^^^^^^^^^^^^^^^^^^^^^^^^^^^^^^^^^^^^^^^^^^^^^^^^^^^^^^^^^^^
  File "C:\Users\NONE\Desktop\pythoN\jopa\.venv\Lib\site-packages\aiogram\dispatcher\router.py", line 141, in _wrapped
    return await self._propagate_event(
           ^^^^^^^^^^^^^^^^^^^^^^^^^^^^
  File "C:\Users\NONE\Desktop\pythoN\jopa\.venv\Lib\site-packages\aiogram\dispatcher\router.py", line 166, in _propagate_event
    response = await observer.trigger(event, **kwargs)
               ^^^^^^^^^^^^^^^^^^^^^^^^^^^^^^^^^^^^^^^
  File "C:\Users\NONE\Desktop\pythoN\jopa\.venv\Lib\site-packages\aiogram\dispatcher\event\telegram.py", line 121, in trigger
    return await wrapped_inner(event, kwargs)
           ^^^^^^^^^^^^^^^^^^^^^^^^^^^^^^^^^^
  File "C:\Users\NONE\Desktop\pythoN\jopa\.venv\Lib\site-packages\aiogram\dispatcher\event\handler.py", line 43, in call
    return await wrapped()
           ^^^^^^^^^^^^^^^
  File "C:\Users\NONE\Desktop\pythoN\jopa\bot\base.py", line 79, in check
    name = data["name"]
           ~~~~^^^^^^^^
KeyError: 'name'
2024-10-20 15:49:01,794 [ ERROR  ] (dispatcher.py:_process_update:315): Cause exception while process update id=758780804 by bot id=8144851601
KeyError: 'name'
Traceback (most recent call last):
  File "C:\Users\NONE\Desktop\pythoN\jopa\.venv\Lib\site-packages\aiogram\dispatcher\dispatcher.py", line 309, in _process_update
    response = await self.feed_update(bot, update, **kwargs)
               ^^^^^^^^^^^^^^^^^^^^^^^^^^^^^^^^^^^^^^^^^^^^^
  File "C:\Users\NONE\Desktop\pythoN\jopa\.venv\Lib\site-packages\aiogram\dispatcher\dispatcher.py", line 158, in feed_update
    response = await self.update.wrap_outer_middleware(
               ^^^^^^^^^^^^^^^^^^^^^^^^^^^^^^^^^^^^^^^^
  File "C:\Users\NONE\Desktop\pythoN\jopa\.venv\Lib\site-packages\aiogram\dispatcher\middlewares\error.py", line 25, in __call__
    return await handler(event, data)
           ^^^^^^^^^^^^^^^^^^^^^^^^^^
  File "C:\Users\NONE\Desktop\pythoN\jopa\.venv\Lib\site-packages\aiogram\dispatcher\middlewares\user_context.py", line 56, in __call__
    return await handler(event, data)
           ^^^^^^^^^^^^^^^^^^^^^^^^^^
  File "C:\Users\NONE\AppData\Local\Programs\Python\Python311\Lib\contextlib.py", line 222, in __aexit__
    await self.gen.athrow(typ, value, traceback)
  File "C:\Users\NONE\Desktop\pythoN\jopa\.venv\Lib\site-packages\aiogram\fsm\storage\memory.py", line 56, in lock
    yield
  File "C:\Users\NONE\Desktop\pythoN\jopa\.venv\Lib\site-packages\aiogram\fsm\middleware.py", line 42, in __call__
    return await handler(event, data)
           ^^^^^^^^^^^^^^^^^^^^^^^^^^
  File "C:\Users\NONE\Desktop\pythoN\jopa\.venv\Lib\site-packages\aiogram\dispatcher\event\telegram.py", line 121, in trigger
    return await wrapped_inner(event, kwargs)
           ^^^^^^^^^^^^^^^^^^^^^^^^^^^^^^^^^^
  File "C:\Users\NONE\Desktop\pythoN\jopa\.venv\Lib\site-packages\aiogram\dispatcher\event\handler.py", line 43, in call
    return await wrapped()
           ^^^^^^^^^^^^^^^
  File "C:\Users\NONE\Desktop\pythoN\jopa\.venv\Lib\site-packages\aiogram\dispatcher\dispatcher.py", line 276, in _listen_update
    return await self.propagate_event(update_type=update_type, event=event, **kwargs)
           ^^^^^^^^^^^^^^^^^^^^^^^^^^^^^^^^^^^^^^^^^^^^^^^^^^^^^^^^^^^^^^^^^^^^^^^^^^
  File "C:\Users\NONE\Desktop\pythoN\jopa\.venv\Lib\site-packages\aiogram\dispatcher\router.py", line 146, in propagate_event
    return await observer.wrap_outer_middleware(_wrapped, event=event, data=kwargs)
           ^^^^^^^^^^^^^^^^^^^^^^^^^^^^^^^^^^^^^^^^^^^^^^^^^^^^^^^^^^^^^^^^^^^^^^^^
  File "C:\Users\NONE\Desktop\pythoN\jopa\.venv\Lib\site-packages\aiogram\dispatcher\router.py", line 141, in _wrapped
    return await self._propagate_event(
           ^^^^^^^^^^^^^^^^^^^^^^^^^^^^
  File "C:\Users\NONE\Desktop\pythoN\jopa\.venv\Lib\site-packages\aiogram\dispatcher\router.py", line 174, in _propagate_event
    response = await router.propagate_event(update_type=update_type, event=event, **kwargs)
               ^^^^^^^^^^^^^^^^^^^^^^^^^^^^^^^^^^^^^^^^^^^^^^^^^^^^^^^^^^^^^^^^^^^^^^^^^^^^
  File "C:\Users\NONE\Desktop\pythoN\jopa\.venv\Lib\site-packages\aiogram\dispatcher\router.py", line 146, in propagate_event
    return await observer.wrap_outer_middleware(_wrapped, event=event, data=kwargs)
           ^^^^^^^^^^^^^^^^^^^^^^^^^^^^^^^^^^^^^^^^^^^^^^^^^^^^^^^^^^^^^^^^^^^^^^^^
  File "C:\Users\NONE\Desktop\pythoN\jopa\.venv\Lib\site-packages\aiogram\dispatcher\router.py", line 141, in _wrapped
    return await self._propagate_event(
           ^^^^^^^^^^^^^^^^^^^^^^^^^^^^
  File "C:\Users\NONE\Desktop\pythoN\jopa\.venv\Lib\site-packages\aiogram\dispatcher\router.py", line 166, in _propagate_event
    response = await observer.trigger(event, **kwargs)
               ^^^^^^^^^^^^^^^^^^^^^^^^^^^^^^^^^^^^^^^
  File "C:\Users\NONE\Desktop\pythoN\jopa\.venv\Lib\site-packages\aiogram\dispatcher\event\telegram.py", line 121, in trigger
    return await wrapped_inner(event, kwargs)
           ^^^^^^^^^^^^^^^^^^^^^^^^^^^^^^^^^^
  File "C:\Users\NONE\Desktop\pythoN\jopa\.venv\Lib\site-packages\aiogram\dispatcher\event\handler.py", line 43, in call
    return await wrapped()
           ^^^^^^^^^^^^^^^
  File "C:\Users\NONE\Desktop\pythoN\jopa\bot\base.py", line 79, in check
    category = data["category"]
           ^^^^^^^^^^^^
KeyError: 'name'
2024-10-20 15:49:02,596 [ ERROR  ] (dispatcher.py:_listen_updates:219): Failed to fetch updates - TelegramNetworkError: HTTP Client says - Request timeout error
2024-10-20 15:49:38,052 [CRITICAL] (main.py:bot_start:18): Error: 
Traceback (most recent call last):
  File "C:\Users\NONE\Desktop\pythoN\jopa\main.py", line 15, in bot_start
    await dp.start_polling(bot)
  File "C:\Users\NONE\Desktop\pythoN\jopa\.venv\Lib\site-packages\aiogram\dispatcher\dispatcher.py", line 543, in start_polling
    done, pending = await asyncio.wait(tasks, return_when=asyncio.FIRST_COMPLETED)
                    ^^^^^^^^^^^^^^^^^^^^^^^^^^^^^^^^^^^^^^^^^^^^^^^^^^^^^^^^^^^^^^
  File "C:\Users\NONE\AppData\Local\Programs\Python\Python311\Lib\asyncio\tasks.py", line 418, in wait
    return await _wait(fs, timeout, return_when, loop)
           ^^^^^^^^^^^^^^^^^^^^^^^^^^^^^^^^^^^^^^^^^^^
  File "C:\Users\NONE\AppData\Local\Programs\Python\Python311\Lib\asyncio\tasks.py", line 525, in _wait
    await waiter
asyncio.exceptions.CancelledError
2024-10-20 15:49:38,055 [CRITICAL] (main.py:main:26): Error: 
Traceback (most recent call last):
  File "C:\Users\NONE\Desktop\pythoN\jopa\main.py", line 24, in main
    await asyncio.gather(bot_app, db_app)
asyncio.exceptions.CancelledError
2024-10-20 15:49:59,136 [ ERROR  ] (dispatcher.py:_process_update:315): Cause exception while process update id=758780810 by bot id=8144851601
KeyError: 'time'
Traceback (most recent call last):
  File "C:\Users\NONE\Desktop\pythoN\jopa\.venv\Lib\site-packages\aiogram\dispatcher\dispatcher.py", line 309, in _process_update
    response = await self.feed_update(bot, update, **kwargs)
               ^^^^^^^^^^^^^^^^^^^^^^^^^^^^^^^^^^^^^^^^^^^^^
  File "C:\Users\NONE\Desktop\pythoN\jopa\.venv\Lib\site-packages\aiogram\dispatcher\dispatcher.py", line 158, in feed_update
    response = await self.update.wrap_outer_middleware(
               ^^^^^^^^^^^^^^^^^^^^^^^^^^^^^^^^^^^^^^^^
  File "C:\Users\NONE\Desktop\pythoN\jopa\.venv\Lib\site-packages\aiogram\dispatcher\middlewares\error.py", line 25, in __call__
    return await handler(event, data)
           ^^^^^^^^^^^^^^^^^^^^^^^^^^
  File "C:\Users\NONE\Desktop\pythoN\jopa\.venv\Lib\site-packages\aiogram\dispatcher\middlewares\user_context.py", line 56, in __call__
    return await handler(event, data)
           ^^^^^^^^^^^^^^^^^^^^^^^^^^
  File "C:\Users\NONE\AppData\Local\Programs\Python\Python311\Lib\contextlib.py", line 222, in __aexit__
    await self.gen.athrow(typ, value, traceback)
  File "C:\Users\NONE\Desktop\pythoN\jopa\.venv\Lib\site-packages\aiogram\fsm\storage\memory.py", line 56, in lock
    yield
  File "C:\Users\NONE\Desktop\pythoN\jopa\.venv\Lib\site-packages\aiogram\fsm\middleware.py", line 42, in __call__
    return await handler(event, data)
           ^^^^^^^^^^^^^^^^^^^^^^^^^^
  File "C:\Users\NONE\Desktop\pythoN\jopa\.venv\Lib\site-packages\aiogram\dispatcher\event\telegram.py", line 121, in trigger
    return await wrapped_inner(event, kwargs)
           ^^^^^^^^^^^^^^^^^^^^^^^^^^^^^^^^^^
  File "C:\Users\NONE\Desktop\pythoN\jopa\.venv\Lib\site-packages\aiogram\dispatcher\event\handler.py", line 43, in call
    return await wrapped()
           ^^^^^^^^^^^^^^^
  File "C:\Users\NONE\Desktop\pythoN\jopa\.venv\Lib\site-packages\aiogram\dispatcher\dispatcher.py", line 276, in _listen_update
    return await self.propagate_event(update_type=update_type, event=event, **kwargs)
           ^^^^^^^^^^^^^^^^^^^^^^^^^^^^^^^^^^^^^^^^^^^^^^^^^^^^^^^^^^^^^^^^^^^^^^^^^^
  File "C:\Users\NONE\Desktop\pythoN\jopa\.venv\Lib\site-packages\aiogram\dispatcher\router.py", line 146, in propagate_event
    return await observer.wrap_outer_middleware(_wrapped, event=event, data=kwargs)
           ^^^^^^^^^^^^^^^^^^^^^^^^^^^^^^^^^^^^^^^^^^^^^^^^^^^^^^^^^^^^^^^^^^^^^^^^
  File "C:\Users\NONE\Desktop\pythoN\jopa\.venv\Lib\site-packages\aiogram\dispatcher\router.py", line 141, in _wrapped
    return await self._propagate_event(
           ^^^^^^^^^^^^^^^^^^^^^^^^^^^^
  File "C:\Users\NONE\Desktop\pythoN\jopa\.venv\Lib\site-packages\aiogram\dispatcher\router.py", line 174, in _propagate_event
    response = await router.propagate_event(update_type=update_type, event=event, **kwargs)
               ^^^^^^^^^^^^^^^^^^^^^^^^^^^^^^^^^^^^^^^^^^^^^^^^^^^^^^^^^^^^^^^^^^^^^^^^^^^^
  File "C:\Users\NONE\Desktop\pythoN\jopa\.venv\Lib\site-packages\aiogram\dispatcher\router.py", line 146, in propagate_event
    return await observer.wrap_outer_middleware(_wrapped, event=event, data=kwargs)
           ^^^^^^^^^^^^^^^^^^^^^^^^^^^^^^^^^^^^^^^^^^^^^^^^^^^^^^^^^^^^^^^^^^^^^^^^
  File "C:\Users\NONE\Desktop\pythoN\jopa\.venv\Lib\site-packages\aiogram\dispatcher\router.py", line 141, in _wrapped
    return await self._propagate_event(
           ^^^^^^^^^^^^^^^^^^^^^^^^^^^^
  File "C:\Users\NONE\Desktop\pythoN\jopa\.venv\Lib\site-packages\aiogram\dispatcher\router.py", line 166, in _propagate_event
    response = await observer.trigger(event, **kwargs)
               ^^^^^^^^^^^^^^^^^^^^^^^^^^^^^^^^^^^^^^^
  File "C:\Users\NONE\Desktop\pythoN\jopa\.venv\Lib\site-packages\aiogram\dispatcher\event\telegram.py", line 121, in trigger
    return await wrapped_inner(event, kwargs)
           ^^^^^^^^^^^^^^^^^^^^^^^^^^^^^^^^^^
  File "C:\Users\NONE\Desktop\pythoN\jopa\.venv\Lib\site-packages\aiogram\dispatcher\event\handler.py", line 43, in call
    return await wrapped()
           ^^^^^^^^^^^^^^^
  File "C:\Users\NONE\Desktop\pythoN\jopa\bot\base.py", line 82, in check
    time = data["time"]
           ~~~~^^^^^^^^
KeyError: 'time'
2024-10-20 15:50:23,809 [ ERROR  ] (dispatcher.py:_process_update:315): Cause exception while process update id=758780811 by bot id=8144851601
KeyError: 'category'
Traceback (most recent call last):
  File "C:\Users\NONE\Desktop\pythoN\jopa\.venv\Lib\site-packages\aiogram\dispatcher\dispatcher.py", line 309, in _process_update
    response = await self.feed_update(bot, update, **kwargs)
               ^^^^^^^^^^^^^^^^^^^^^^^^^^^^^^^^^^^^^^^^^^^^^
  File "C:\Users\NONE\Desktop\pythoN\jopa\.venv\Lib\site-packages\aiogram\dispatcher\dispatcher.py", line 158, in feed_update
    response = await self.update.wrap_outer_middleware(
               ^^^^^^^^^^^^^^^^^^^^^^^^^^^^^^^^^^^^^^^^
  File "C:\Users\NONE\Desktop\pythoN\jopa\.venv\Lib\site-packages\aiogram\dispatcher\middlewares\error.py", line 25, in __call__
    return await handler(event, data)
           ^^^^^^^^^^^^^^^^^^^^^^^^^^
  File "C:\Users\NONE\Desktop\pythoN\jopa\.venv\Lib\site-packages\aiogram\dispatcher\middlewares\user_context.py", line 56, in __call__
    return await handler(event, data)
           ^^^^^^^^^^^^^^^^^^^^^^^^^^
  File "C:\Users\NONE\AppData\Local\Programs\Python\Python311\Lib\contextlib.py", line 222, in __aexit__
    await self.gen.athrow(typ, value, traceback)
  File "C:\Users\NONE\Desktop\pythoN\jopa\.venv\Lib\site-packages\aiogram\fsm\storage\memory.py", line 56, in lock
    yield
  File "C:\Users\NONE\Desktop\pythoN\jopa\.venv\Lib\site-packages\aiogram\fsm\middleware.py", line 42, in __call__
    return await handler(event, data)
           ^^^^^^^^^^^^^^^^^^^^^^^^^^
  File "C:\Users\NONE\Desktop\pythoN\jopa\.venv\Lib\site-packages\aiogram\dispatcher\event\telegram.py", line 121, in trigger
    return await wrapped_inner(event, kwargs)
           ^^^^^^^^^^^^^^^^^^^^^^^^^^^^^^^^^^
  File "C:\Users\NONE\Desktop\pythoN\jopa\.venv\Lib\site-packages\aiogram\dispatcher\event\handler.py", line 43, in call
    return await wrapped()
           ^^^^^^^^^^^^^^^
  File "C:\Users\NONE\Desktop\pythoN\jopa\.venv\Lib\site-packages\aiogram\dispatcher\dispatcher.py", line 276, in _listen_update
    return await self.propagate_event(update_type=update_type, event=event, **kwargs)
           ^^^^^^^^^^^^^^^^^^^^^^^^^^^^^^^^^^^^^^^^^^^^^^^^^^^^^^^^^^^^^^^^^^^^^^^^^^
  File "C:\Users\NONE\Desktop\pythoN\jopa\.venv\Lib\site-packages\aiogram\dispatcher\router.py", line 146, in propagate_event
    return await observer.wrap_outer_middleware(_wrapped, event=event, data=kwargs)
           ^^^^^^^^^^^^^^^^^^^^^^^^^^^^^^^^^^^^^^^^^^^^^^^^^^^^^^^^^^^^^^^^^^^^^^^^
  File "C:\Users\NONE\Desktop\pythoN\jopa\.venv\Lib\site-packages\aiogram\dispatcher\router.py", line 141, in _wrapped
    return await self._propagate_event(
           ^^^^^^^^^^^^^^^^^^^^^^^^^^^^
  File "C:\Users\NONE\Desktop\pythoN\jopa\.venv\Lib\site-packages\aiogram\dispatcher\router.py", line 174, in _propagate_event
    response = await router.propagate_event(update_type=update_type, event=event, **kwargs)
               ^^^^^^^^^^^^^^^^^^^^^^^^^^^^^^^^^^^^^^^^^^^^^^^^^^^^^^^^^^^^^^^^^^^^^^^^^^^^
  File "C:\Users\NONE\Desktop\pythoN\jopa\.venv\Lib\site-packages\aiogram\dispatcher\router.py", line 146, in propagate_event
    return await observer.wrap_outer_middleware(_wrapped, event=event, data=kwargs)
           ^^^^^^^^^^^^^^^^^^^^^^^^^^^^^^^^^^^^^^^^^^^^^^^^^^^^^^^^^^^^^^^^^^^^^^^^
  File "C:\Users\NONE\Desktop\pythoN\jopa\.venv\Lib\site-packages\aiogram\dispatcher\router.py", line 141, in _wrapped
    return await self._propagate_event(
           ^^^^^^^^^^^^^^^^^^^^^^^^^^^^
  File "C:\Users\NONE\Desktop\pythoN\jopa\.venv\Lib\site-packages\aiogram\dispatcher\router.py", line 166, in _propagate_event
    response = await observer.trigger(event, **kwargs)
               ^^^^^^^^^^^^^^^^^^^^^^^^^^^^^^^^^^^^^^^
  File "C:\Users\NONE\Desktop\pythoN\jopa\.venv\Lib\site-packages\aiogram\dispatcher\event\telegram.py", line 121, in trigger
    return await wrapped_inner(event, kwargs)
           ^^^^^^^^^^^^^^^^^^^^^^^^^^^^^^^^^^
  File "C:\Users\NONE\Desktop\pythoN\jopa\.venv\Lib\site-packages\aiogram\dispatcher\event\handler.py", line 43, in call
    return await wrapped()
           ^^^^^^^^^^^^^^^
  File "C:\Users\NONE\Desktop\pythoN\jopa\bot\base.py", line 79, in check
    category = data["category"]
               ~~~~^^^^^^^^^^^^
KeyError: 'category'
2024-10-20 15:53:25,697 [ ERROR  ] (dispatcher.py:_process_update:315): Cause exception while process update id=758780821 by bot id=8144851601
KeyError: 'category'
Traceback (most recent call last):
  File "C:\Users\NONE\Desktop\pythoN\jopa\.venv\Lib\site-packages\aiogram\dispatcher\dispatcher.py", line 309, in _process_update
    response = await self.feed_update(bot, update, **kwargs)
               ^^^^^^^^^^^^^^^^^^^^^^^^^^^^^^^^^^^^^^^^^^^^^
  File "C:\Users\NONE\Desktop\pythoN\jopa\.venv\Lib\site-packages\aiogram\dispatcher\dispatcher.py", line 158, in feed_update
    response = await self.update.wrap_outer_middleware(
               ^^^^^^^^^^^^^^^^^^^^^^^^^^^^^^^^^^^^^^^^
  File "C:\Users\NONE\Desktop\pythoN\jopa\.venv\Lib\site-packages\aiogram\dispatcher\middlewares\error.py", line 25, in __call__
    return await handler(event, data)
           ^^^^^^^^^^^^^^^^^^^^^^^^^^
  File "C:\Users\NONE\Desktop\pythoN\jopa\.venv\Lib\site-packages\aiogram\dispatcher\middlewares\user_context.py", line 56, in __call__
    return await handler(event, data)
           ^^^^^^^^^^^^^^^^^^^^^^^^^^
  File "C:\Users\NONE\AppData\Local\Programs\Python\Python311\Lib\contextlib.py", line 222, in __aexit__
    await self.gen.athrow(typ, value, traceback)
  File "C:\Users\NONE\Desktop\pythoN\jopa\.venv\Lib\site-packages\aiogram\fsm\storage\memory.py", line 56, in lock
    yield
  File "C:\Users\NONE\Desktop\pythoN\jopa\.venv\Lib\site-packages\aiogram\fsm\middleware.py", line 42, in __call__
    return await handler(event, data)
           ^^^^^^^^^^^^^^^^^^^^^^^^^^
  File "C:\Users\NONE\Desktop\pythoN\jopa\.venv\Lib\site-packages\aiogram\dispatcher\event\telegram.py", line 121, in trigger
    return await wrapped_inner(event, kwargs)
           ^^^^^^^^^^^^^^^^^^^^^^^^^^^^^^^^^^
  File "C:\Users\NONE\Desktop\pythoN\jopa\.venv\Lib\site-packages\aiogram\dispatcher\event\handler.py", line 43, in call
    return await wrapped()
           ^^^^^^^^^^^^^^^
  File "C:\Users\NONE\Desktop\pythoN\jopa\.venv\Lib\site-packages\aiogram\dispatcher\dispatcher.py", line 276, in _listen_update
    return await self.propagate_event(update_type=update_type, event=event, **kwargs)
           ^^^^^^^^^^^^^^^^^^^^^^^^^^^^^^^^^^^^^^^^^^^^^^^^^^^^^^^^^^^^^^^^^^^^^^^^^^
  File "C:\Users\NONE\Desktop\pythoN\jopa\.venv\Lib\site-packages\aiogram\dispatcher\router.py", line 146, in propagate_event
    return await observer.wrap_outer_middleware(_wrapped, event=event, data=kwargs)
           ^^^^^^^^^^^^^^^^^^^^^^^^^^^^^^^^^^^^^^^^^^^^^^^^^^^^^^^^^^^^^^^^^^^^^^^^
  File "C:\Users\NONE\Desktop\pythoN\jopa\.venv\Lib\site-packages\aiogram\dispatcher\router.py", line 141, in _wrapped
    return await self._propagate_event(
           ^^^^^^^^^^^^^^^^^^^^^^^^^^^^
  File "C:\Users\NONE\Desktop\pythoN\jopa\.venv\Lib\site-packages\aiogram\dispatcher\router.py", line 174, in _propagate_event
    response = await router.propagate_event(update_type=update_type, event=event, **kwargs)
               ^^^^^^^^^^^^^^^^^^^^^^^^^^^^^^^^^^^^^^^^^^^^^^^^^^^^^^^^^^^^^^^^^^^^^^^^^^^^
  File "C:\Users\NONE\Desktop\pythoN\jopa\.venv\Lib\site-packages\aiogram\dispatcher\router.py", line 146, in propagate_event
    return await observer.wrap_outer_middleware(_wrapped, event=event, data=kwargs)
           ^^^^^^^^^^^^^^^^^^^^^^^^^^^^^^^^^^^^^^^^^^^^^^^^^^^^^^^^^^^^^^^^^^^^^^^^
  File "C:\Users\NONE\Desktop\pythoN\jopa\.venv\Lib\site-packages\aiogram\dispatcher\router.py", line 141, in _wrapped
    return await self._propagate_event(
           ^^^^^^^^^^^^^^^^^^^^^^^^^^^^
  File "C:\Users\NONE\Desktop\pythoN\jopa\.venv\Lib\site-packages\aiogram\dispatcher\router.py", line 166, in _propagate_event
    response = await observer.trigger(event, **kwargs)
               ^^^^^^^^^^^^^^^^^^^^^^^^^^^^^^^^^^^^^^^
  File "C:\Users\NONE\Desktop\pythoN\jopa\.venv\Lib\site-packages\aiogram\dispatcher\event\telegram.py", line 121, in trigger
    return await wrapped_inner(event, kwargs)
           ^^^^^^^^^^^^^^^^^^^^^^^^^^^^^^^^^^
  File "C:\Users\NONE\Desktop\pythoN\jopa\.venv\Lib\site-packages\aiogram\dispatcher\event\handler.py", line 43, in call
    return await wrapped()
           ^^^^^^^^^^^^^^^
  File "C:\Users\NONE\Desktop\pythoN\jopa\bot\base.py", line 80, in check
    category = data["category"]
               ~~~~^^^^^^^^^^^^
KeyError: 'category'
2024-10-20 15:53:43,593 [ ERROR  ] (dispatcher.py:_process_update:315): Cause exception while process update id=758780826 by bot id=8144851601
IndexError: list index out of range
Traceback (most recent call last):
  File "C:\Users\NONE\Desktop\pythoN\jopa\.venv\Lib\site-packages\aiogram\dispatcher\dispatcher.py", line 309, in _process_update
    response = await self.feed_update(bot, update, **kwargs)
               ^^^^^^^^^^^^^^^^^^^^^^^^^^^^^^^^^^^^^^^^^^^^^
  File "C:\Users\NONE\Desktop\pythoN\jopa\.venv\Lib\site-packages\aiogram\dispatcher\dispatcher.py", line 158, in feed_update
    response = await self.update.wrap_outer_middleware(
               ^^^^^^^^^^^^^^^^^^^^^^^^^^^^^^^^^^^^^^^^
  File "C:\Users\NONE\Desktop\pythoN\jopa\.venv\Lib\site-packages\aiogram\dispatcher\middlewares\error.py", line 25, in __call__
    return await handler(event, data)
           ^^^^^^^^^^^^^^^^^^^^^^^^^^
  File "C:\Users\NONE\Desktop\pythoN\jopa\.venv\Lib\site-packages\aiogram\dispatcher\middlewares\user_context.py", line 56, in __call__
    return await handler(event, data)
           ^^^^^^^^^^^^^^^^^^^^^^^^^^
  File "C:\Users\NONE\AppData\Local\Programs\Python\Python311\Lib\contextlib.py", line 222, in __aexit__
    await self.gen.athrow(typ, value, traceback)
  File "C:\Users\NONE\Desktop\pythoN\jopa\.venv\Lib\site-packages\aiogram\fsm\storage\memory.py", line 56, in lock
    yield
  File "C:\Users\NONE\Desktop\pythoN\jopa\.venv\Lib\site-packages\aiogram\fsm\middleware.py", line 42, in __call__
    return await handler(event, data)
           ^^^^^^^^^^^^^^^^^^^^^^^^^^
  File "C:\Users\NONE\Desktop\pythoN\jopa\.venv\Lib\site-packages\aiogram\dispatcher\event\telegram.py", line 121, in trigger
    return await wrapped_inner(event, kwargs)
           ^^^^^^^^^^^^^^^^^^^^^^^^^^^^^^^^^^
  File "C:\Users\NONE\Desktop\pythoN\jopa\.venv\Lib\site-packages\aiogram\dispatcher\event\handler.py", line 43, in call
    return await wrapped()
           ^^^^^^^^^^^^^^^
  File "C:\Users\NONE\Desktop\pythoN\jopa\.venv\Lib\site-packages\aiogram\dispatcher\dispatcher.py", line 276, in _listen_update
    return await self.propagate_event(update_type=update_type, event=event, **kwargs)
           ^^^^^^^^^^^^^^^^^^^^^^^^^^^^^^^^^^^^^^^^^^^^^^^^^^^^^^^^^^^^^^^^^^^^^^^^^^
  File "C:\Users\NONE\Desktop\pythoN\jopa\.venv\Lib\site-packages\aiogram\dispatcher\router.py", line 146, in propagate_event
    return await observer.wrap_outer_middleware(_wrapped, event=event, data=kwargs)
           ^^^^^^^^^^^^^^^^^^^^^^^^^^^^^^^^^^^^^^^^^^^^^^^^^^^^^^^^^^^^^^^^^^^^^^^^
  File "C:\Users\NONE\Desktop\pythoN\jopa\.venv\Lib\site-packages\aiogram\dispatcher\router.py", line 141, in _wrapped
    return await self._propagate_event(
           ^^^^^^^^^^^^^^^^^^^^^^^^^^^^
  File "C:\Users\NONE\Desktop\pythoN\jopa\.venv\Lib\site-packages\aiogram\dispatcher\router.py", line 174, in _propagate_event
    response = await router.propagate_event(update_type=update_type, event=event, **kwargs)
               ^^^^^^^^^^^^^^^^^^^^^^^^^^^^^^^^^^^^^^^^^^^^^^^^^^^^^^^^^^^^^^^^^^^^^^^^^^^^
  File "C:\Users\NONE\Desktop\pythoN\jopa\.venv\Lib\site-packages\aiogram\dispatcher\router.py", line 146, in propagate_event
    return await observer.wrap_outer_middleware(_wrapped, event=event, data=kwargs)
           ^^^^^^^^^^^^^^^^^^^^^^^^^^^^^^^^^^^^^^^^^^^^^^^^^^^^^^^^^^^^^^^^^^^^^^^^
  File "C:\Users\NONE\Desktop\pythoN\jopa\.venv\Lib\site-packages\aiogram\dispatcher\router.py", line 141, in _wrapped
    return await self._propagate_event(
           ^^^^^^^^^^^^^^^^^^^^^^^^^^^^
  File "C:\Users\NONE\Desktop\pythoN\jopa\.venv\Lib\site-packages\aiogram\dispatcher\router.py", line 166, in _propagate_event
    response = await observer.trigger(event, **kwargs)
               ^^^^^^^^^^^^^^^^^^^^^^^^^^^^^^^^^^^^^^^
  File "C:\Users\NONE\Desktop\pythoN\jopa\.venv\Lib\site-packages\aiogram\dispatcher\event\telegram.py", line 121, in trigger
    return await wrapped_inner(event, kwargs)
           ^^^^^^^^^^^^^^^^^^^^^^^^^^^^^^^^^^
  File "C:\Users\NONE\Desktop\pythoN\jopa\.venv\Lib\site-packages\aiogram\dispatcher\event\handler.py", line 43, in call
    return await wrapped()
           ^^^^^^^^^^^^^^^
  File "C:\Users\NONE\Desktop\pythoN\jopa\bot\base.py", line 85, in check
IndexError: list index out of range
2024-10-20 15:53:49,425 [ ERROR  ] (dispatcher.py:_process_update:315): Cause exception while process update id=758780827 by bot id=8144851601
IndexError: list index out of range
Traceback (most recent call last):
  File "C:\Users\NONE\Desktop\pythoN\jopa\.venv\Lib\site-packages\aiogram\dispatcher\dispatcher.py", line 309, in _process_update
    response = await self.feed_update(bot, update, **kwargs)
               ^^^^^^^^^^^^^^^^^^^^^^^^^^^^^^^^^^^^^^^^^^^^^
  File "C:\Users\NONE\Desktop\pythoN\jopa\.venv\Lib\site-packages\aiogram\dispatcher\dispatcher.py", line 158, in feed_update
    response = await self.update.wrap_outer_middleware(
               ^^^^^^^^^^^^^^^^^^^^^^^^^^^^^^^^^^^^^^^^
  File "C:\Users\NONE\Desktop\pythoN\jopa\.venv\Lib\site-packages\aiogram\dispatcher\middlewares\error.py", line 25, in __call__
    return await handler(event, data)
           ^^^^^^^^^^^^^^^^^^^^^^^^^^
  File "C:\Users\NONE\Desktop\pythoN\jopa\.venv\Lib\site-packages\aiogram\dispatcher\middlewares\user_context.py", line 56, in __call__
    return await handler(event, data)
           ^^^^^^^^^^^^^^^^^^^^^^^^^^
  File "C:\Users\NONE\AppData\Local\Programs\Python\Python311\Lib\contextlib.py", line 222, in __aexit__
    await self.gen.athrow(typ, value, traceback)
  File "C:\Users\NONE\Desktop\pythoN\jopa\.venv\Lib\site-packages\aiogram\fsm\storage\memory.py", line 56, in lock
    yield
  File "C:\Users\NONE\Desktop\pythoN\jopa\.venv\Lib\site-packages\aiogram\fsm\middleware.py", line 42, in __call__
    return await handler(event, data)
           ^^^^^^^^^^^^^^^^^^^^^^^^^^
  File "C:\Users\NONE\Desktop\pythoN\jopa\.venv\Lib\site-packages\aiogram\dispatcher\event\telegram.py", line 121, in trigger
    return await wrapped_inner(event, kwargs)
           ^^^^^^^^^^^^^^^^^^^^^^^^^^^^^^^^^^
  File "C:\Users\NONE\Desktop\pythoN\jopa\.venv\Lib\site-packages\aiogram\dispatcher\event\handler.py", line 43, in call
    return await wrapped()
           ^^^^^^^^^^^^^^^
  File "C:\Users\NONE\Desktop\pythoN\jopa\.venv\Lib\site-packages\aiogram\dispatcher\dispatcher.py", line 276, in _listen_update
    return await self.propagate_event(update_type=update_type, event=event, **kwargs)
           ^^^^^^^^^^^^^^^^^^^^^^^^^^^^^^^^^^^^^^^^^^^^^^^^^^^^^^^^^^^^^^^^^^^^^^^^^^
  File "C:\Users\NONE\Desktop\pythoN\jopa\.venv\Lib\site-packages\aiogram\dispatcher\router.py", line 146, in propagate_event
    return await observer.wrap_outer_middleware(_wrapped, event=event, data=kwargs)
           ^^^^^^^^^^^^^^^^^^^^^^^^^^^^^^^^^^^^^^^^^^^^^^^^^^^^^^^^^^^^^^^^^^^^^^^^
  File "C:\Users\NONE\Desktop\pythoN\jopa\.venv\Lib\site-packages\aiogram\dispatcher\router.py", line 141, in _wrapped
    return await self._propagate_event(
           ^^^^^^^^^^^^^^^^^^^^^^^^^^^^
  File "C:\Users\NONE\Desktop\pythoN\jopa\.venv\Lib\site-packages\aiogram\dispatcher\router.py", line 174, in _propagate_event
    response = await router.propagate_event(update_type=update_type, event=event, **kwargs)
               ^^^^^^^^^^^^^^^^^^^^^^^^^^^^^^^^^^^^^^^^^^^^^^^^^^^^^^^^^^^^^^^^^^^^^^^^^^^^
  File "C:\Users\NONE\Desktop\pythoN\jopa\.venv\Lib\site-packages\aiogram\dispatcher\router.py", line 146, in propagate_event
    return await observer.wrap_outer_middleware(_wrapped, event=event, data=kwargs)
           ^^^^^^^^^^^^^^^^^^^^^^^^^^^^^^^^^^^^^^^^^^^^^^^^^^^^^^^^^^^^^^^^^^^^^^^^
  File "C:\Users\NONE\Desktop\pythoN\jopa\.venv\Lib\site-packages\aiogram\dispatcher\router.py", line 141, in _wrapped
    return await self._propagate_event(
           ^^^^^^^^^^^^^^^^^^^^^^^^^^^^
  File "C:\Users\NONE\Desktop\pythoN\jopa\.venv\Lib\site-packages\aiogram\dispatcher\router.py", line 166, in _propagate_event
    response = await observer.trigger(event, **kwargs)
               ^^^^^^^^^^^^^^^^^^^^^^^^^^^^^^^^^^^^^^^
  File "C:\Users\NONE\Desktop\pythoN\jopa\.venv\Lib\site-packages\aiogram\dispatcher\event\telegram.py", line 121, in trigger
    return await wrapped_inner(event, kwargs)
           ^^^^^^^^^^^^^^^^^^^^^^^^^^^^^^^^^^
  File "C:\Users\NONE\Desktop\pythoN\jopa\.venv\Lib\site-packages\aiogram\dispatcher\event\handler.py", line 43, in call
    return await wrapped()
           ^^^^^^^^^^^^^^^
  File "C:\Users\NONE\Desktop\pythoN\jopa\bot\base.py", line 85, in check
IndexError: list index out of range
